{
  "id": "MAL-2024-5624",
  "summary": "Malicious code in py-cpord (PyPI)",
  "details": "\n---\n_-= Per source details. Do not edit below this line.=-_\n",
  "aliases": [
    "SNYK-PYTHON-PYCPORD-6513285"
  ],
  "modified": "2024-10-24T01:01:59Z",
  "published": "2024-06-25T13:39:19Z",
  "database_specific": {
    "malicious-packages-origins": [
      {
        "sha256": "314fa7d8daf76d6677f90966ac7770fd5968dd6ba30c49db2345d1b8c48ffad2",
        "import_time": "2024-06-28T02:49:56.606887076Z",
        "versions": [
          "1.0.0"
        ],
        "id": "RLMA-2024-04406",
        "source": "reversing-labs",
        "modified_time": "2024-06-25T13:39:19Z"
      },
      {
        "sha256": "9659a7fcd46e7c998b8f2148af147c399ff44537c203daf81babbca1b5961d3a",
        "import_time": "2024-10-24T00:59:45.265351036Z",
        "id": "RLUA-2024-08839",
        "source": "reversing-labs",
        "modified_time": "2024-10-16T14:46:59Z"
      }
    ]
  },
  "references": [
    {
      "type": "ADVISORY",
      "url": "https://security.snyk.io/vuln/SNYK-PYTHON-PYCPORD-6513285"
    },
    {
      "type": "ARTICLE",
      "url": "https://medium.com/checkmarx-security/pypi-is-under-attack-project-creation-and-user-registration-suspended-heres-the-details-c3b6291d4579"
    }
  ],
  "affected": [
    {
      "package": {
        "name": "py-cpord",
        "ecosystem": "PyPI",
        "purl": "pkg:pypi/py-cpord"
      },
      "versions": [
        "1.0.0"
      ],
      "database_specific": {
        "source": "https://github.com/ossf/malicious-packages/blob/main/osv/malicious/pypi/py-cpord/MAL-2024-5624.json"
      }
    }
  ],
  "schema_version": "1.6.0",
  "credits": [
    {
      "name": "ReversingLabs",
      "contact": [
        "https://www.reversinglabs.com"
      ],
      "type": "FINDER"
    }
  ]
}