{
  "affected": [
    {
      "database_specific": {
        "source": "https://github.com/ossf/malicious-packages/blob/main/osv/malicious/pypi/chatgpt4/MAL-2025-6477.json"
      },
      "package": {
        "ecosystem": "PyPI",
        "name": "chatgpt4",
        "purl": "pkg:pypi/chatgpt4"
      },
      "versions": [
        "0.1",
        "0.2",
        "0.3",
        "0.4",
        "0.5",
        "0.6"
      ]
    }
  ],
  "credits": [
    {
      "contact": [
        "https://www.reversinglabs.com"
      ],
      "name": "ReversingLabs",
      "type": "FINDER"
    }
  ],
  "database_specific": {
    "malicious-packages-origins": [
      {
        "id": "RLMA-2025-03562",
        "import_time": "2025-08-01T10:07:10.337963758Z",
        "modified_time": "2025-07-31T19:14:33Z",
        "sha256": "7a8331f5ca6bada0fe15620d9e7f9285ab01a3a837aaf8026e96c29b0a3bd15a",
        "source": "reversing-labs",
        "versions": [
          "0.1",
          "0.2",
          "0.3",
          "0.4",
          "0.5",
          "0.6"
        ]
      }
    ]
  },
  "details": "\n---\n_-= Per source details. Do not edit below this line.=-_\n",
  "id": "MAL-2025-6477",
  "modified": "2025-07-31T19:14:33Z",
  "published": "2025-07-31T19:14:33Z",
  "schema_version": "1.7.3",
  "summary": "Malicious code in chatgpt4 (PyPI)"
}