{
  "affected": [
    {
      "database_specific": {
        "source": "https://ftp.suse.com/pub/projects/security/osv/openSUSE-SU-2018:0632-1.json"
      },
      "ecosystem_specific": {
        "binaries": [
          {
            "python-Django": "1.11.10-5.1"
          }
        ]
      },
      "package": {
        "ecosystem": "SUSE:Package Hub 12",
        "name": "python-Django",
        "purl": "pkg:rpm/suse/python-Django&distro=SUSE%20Package%20Hub%2012"
      },
      "ranges": [
        {
          "events": [
            {
              "introduced": "0"
            },
            {
              "fixed": "1.11.10-5.1"
            }
          ],
          "type": "ECOSYSTEM"
        }
      ],
      "versions": []
    }
  ],
  "details": "This update for python-Django fixes the following issues:\n  Update to version 1.11.10 LTS\n  * Fixes CVE-2018-6188 boo#1077714, CVE-2017-7234, CVE-2017-7233,\n    CVE-2017-12794\n",
  "id": "openSUSE-SU-2018:0632-1",
  "modified": "2025-05-02T04:29:59.562155Z",
  "published": "2018-03-07T13:14:36Z",
  "references": [
    {
      "type": "ADVISORY"
    },
    {
      "type": "REPORT",
      "url": "https://bugzilla.suse.com/1077714"
    },
    {
      "type": "WEB",
      "url": "https://www.suse.com/security/cve/CVE-2017-12794"
    },
    {
      "type": "WEB",
      "url": "https://www.suse.com/security/cve/CVE-2017-7233"
    },
    {
      "type": "WEB",
      "url": "https://www.suse.com/security/cve/CVE-2017-7234"
    },
    {
      "type": "WEB",
      "url": "https://www.suse.com/security/cve/CVE-2018-6188"
    }
  ],
  "related": [
    "CVE-2017-12794",
    "CVE-2017-7233",
    "CVE-2017-7234",
    "CVE-2018-6188"
  ],
  "schema_version": "1.7.0",
  "summary": "Security update for python-Django",
  "upstream": [
    "CVE-2017-12794",
    "CVE-2017-7233",
    "CVE-2017-7234",
    "CVE-2018-6188"
  ]
}